2021-08-22 13:10:59,633 ERROR: Exception on /login [POST] [in D:\CODE\python\lib\site-packages\flask\app.py:1454]
Traceback (most recent call last):
  File "D:\CODE\python\lib\site-packages\sqlalchemy\util\_collections.py", line 1008, in __call__
    return self.registry[key]
KeyError: <greenlet.greenlet object at 0x00000270324B8670 (otid=0x000002703247A700) current active started main>

During handling of the above exception, another exception occurred:

Traceback (most recent call last):
  File "D:\CODE\python\lib\site-packages\flask\app.py", line 2070, in wsgi_app
    response = self.full_dispatch_request()
  File "D:\CODE\python\lib\site-packages\flask\app.py", line 1515, in full_dispatch_request
    rv = self.handle_user_exception(e)
  File "D:\CODE\python\lib\site-packages\flask\app.py", line 1513, in full_dispatch_request
    rv = self.dispatch_request()
  File "D:\CODE\python\lib\site-packages\flask\app.py", line 1499, in dispatch_request
    return self.ensure_sync(self.view_functions[rule.endpoint])(**req.view_args)
  File "D:\WS\WORK\crmdancer-master\main.py", line 157, in login
    row = User.query.filter_by(login=f['usern'], passw=f['passw']).first()
  File "D:\CODE\python\lib\site-packages\flask_sqlalchemy\__init__.py", line 552, in __get__
    return type.query_class(mapper, session=self.sa.session())
  File "D:\CODE\python\lib\site-packages\sqlalchemy\orm\scoping.py", line 47, in __call__
    return self.registry()
  File "D:\CODE\python\lib\site-packages\sqlalchemy\util\_collections.py", line 1010, in __call__
    return self.registry.setdefault(key, self.createfunc())
  File "D:\CODE\python\lib\site-packages\sqlalchemy\orm\session.py", line 4101, in __call__
    return self.class_(**local_kw)
  File "D:\CODE\python\lib\site-packages\flask_sqlalchemy\__init__.py", line 176, in __init__
    bind = options.pop('bind', None) or db.engine
  File "D:\CODE\python\lib\site-packages\flask_sqlalchemy\__init__.py", line 998, in engine
    return self.get_engine()
  File "D:\CODE\python\lib\site-packages\flask_sqlalchemy\__init__.py", line 1017, in get_engine
    return connector.get_engine()
  File "D:\CODE\python\lib\site-packages\flask_sqlalchemy\__init__.py", line 594, in get_engine
    self._engine = rv = self._sa.create_engine(sa_url, options)
  File "D:\CODE\python\lib\site-packages\flask_sqlalchemy\__init__.py", line 1027, in create_engine
    return sqlalchemy.create_engine(sa_url, **engine_opts)
  File "<string>", line 2, in create_engine
  File "D:\CODE\python\lib\site-packages\sqlalchemy\util\deprecations.py", line 298, in warned
    return fn(*args, **kwargs)
  File "D:\CODE\python\lib\site-packages\sqlalchemy\engine\create.py", line 548, in create_engine
    dbapi = dialect_cls.dbapi(**dbapi_args)
  File "D:\CODE\python\lib\site-packages\sqlalchemy\dialects\mysql\mysqlconnector.py", line 129, in dbapi
    from mysql import connector
ModuleNotFoundError: No module named 'mysql'
2021-08-22 15:14:59,710 ERROR: Exception on /area/crm/ [GET] [in D:\CODE\python\lib\site-packages\flask\app.py:1454]
Traceback (most recent call last):
  File "D:\CODE\python\lib\site-packages\flask\app.py", line 2070, in wsgi_app
    response = self.full_dispatch_request()
  File "D:\CODE\python\lib\site-packages\flask\app.py", line 1515, in full_dispatch_request
    rv = self.handle_user_exception(e)
  File "D:\CODE\python\lib\site-packages\flask\app.py", line 1513, in full_dispatch_request
    rv = self.dispatch_request()
  File "D:\CODE\python\lib\site-packages\flask\app.py", line 1499, in dispatch_request
    return self.ensure_sync(self.view_functions[rule.endpoint])(**req.view_args)
  File "D:\WS\WORK\crmdancer-master\main.py", line 240, in area_crm
    return render_template("crm_index.html")
  File "D:\CODE\python\lib\site-packages\flask\templating.py", line 148, in render_template
    ctx.app.jinja_env.get_or_select_template(template_name_or_list),
  File "D:\CODE\python\lib\site-packages\jinja2\environment.py", line 1068, in get_or_select_template
    return self.get_template(template_name_or_list, parent, globals)
  File "D:\CODE\python\lib\site-packages\jinja2\environment.py", line 997, in get_template
    return self._load_template(name, globals)
  File "D:\CODE\python\lib\site-packages\jinja2\environment.py", line 958, in _load_template
    template = self.loader.load(self, name, self.make_globals(globals))
  File "D:\CODE\python\lib\site-packages\jinja2\loaders.py", line 137, in load
    code = environment.compile(source, name, filename)
  File "D:\CODE\python\lib\site-packages\jinja2\environment.py", line 757, in compile
    self.handle_exception(source=source_hint)
  File "D:\CODE\python\lib\site-packages\jinja2\environment.py", line 925, in handle_exception
    raise rewrite_traceback_stack(source=source)
  File "D:\WS\WORK\crmdancer-master\templates\crm_index.html", line 497, in template
    {% endblock %}
jinja2.exceptions.TemplateSyntaxError: Encountered unknown tag 'endblock'.
2021-08-22 15:15:04,757 ERROR: Exception on /area/crm/ [GET] [in D:\CODE\python\lib\site-packages\flask\app.py:1454]
Traceback (most recent call last):
  File "D:\CODE\python\lib\site-packages\flask\app.py", line 2070, in wsgi_app
    response = self.full_dispatch_request()
  File "D:\CODE\python\lib\site-packages\flask\app.py", line 1515, in full_dispatch_request
    rv = self.handle_user_exception(e)
  File "D:\CODE\python\lib\site-packages\flask\app.py", line 1513, in full_dispatch_request
    rv = self.dispatch_request()
  File "D:\CODE\python\lib\site-packages\flask\app.py", line 1499, in dispatch_request
    return self.ensure_sync(self.view_functions[rule.endpoint])(**req.view_args)
  File "D:\WS\WORK\crmdancer-master\main.py", line 240, in area_crm
    return render_template("crm_index.html")
  File "D:\CODE\python\lib\site-packages\flask\templating.py", line 148, in render_template
    ctx.app.jinja_env.get_or_select_template(template_name_or_list),
  File "D:\CODE\python\lib\site-packages\jinja2\environment.py", line 1068, in get_or_select_template
    return self.get_template(template_name_or_list, parent, globals)
  File "D:\CODE\python\lib\site-packages\jinja2\environment.py", line 997, in get_template
    return self._load_template(name, globals)
  File "D:\CODE\python\lib\site-packages\jinja2\environment.py", line 958, in _load_template
    template = self.loader.load(self, name, self.make_globals(globals))
  File "D:\CODE\python\lib\site-packages\jinja2\loaders.py", line 137, in load
    code = environment.compile(source, name, filename)
  File "D:\CODE\python\lib\site-packages\jinja2\environment.py", line 757, in compile
    self.handle_exception(source=source_hint)
  File "D:\CODE\python\lib\site-packages\jinja2\environment.py", line 925, in handle_exception
    raise rewrite_traceback_stack(source=source)
  File "D:\WS\WORK\crmdancer-master\templates\crm_index.html", line 497, in template
    {% endblock %}
jinja2.exceptions.TemplateSyntaxError: Encountered unknown tag 'endblock'.
2021-08-22 15:15:30,817 ERROR: Exception on /area/crm/ [GET] [in D:\CODE\python\lib\site-packages\flask\app.py:1454]
Traceback (most recent call last):
  File "D:\CODE\python\lib\site-packages\flask\app.py", line 2070, in wsgi_app
    response = self.full_dispatch_request()
  File "D:\CODE\python\lib\site-packages\flask\app.py", line 1515, in full_dispatch_request
    rv = self.handle_user_exception(e)
  File "D:\CODE\python\lib\site-packages\flask\app.py", line 1513, in full_dispatch_request
    rv = self.dispatch_request()
  File "D:\CODE\python\lib\site-packages\flask\app.py", line 1499, in dispatch_request
    return self.ensure_sync(self.view_functions[rule.endpoint])(**req.view_args)
  File "D:\WS\WORK\crmdancer-master\main.py", line 240, in area_crm
    return render_template("crm_index.html")
  File "D:\CODE\python\lib\site-packages\flask\templating.py", line 148, in render_template
    ctx.app.jinja_env.get_or_select_template(template_name_or_list),
  File "D:\CODE\python\lib\site-packages\jinja2\environment.py", line 1068, in get_or_select_template
    return self.get_template(template_name_or_list, parent, globals)
  File "D:\CODE\python\lib\site-packages\jinja2\environment.py", line 997, in get_template
    return self._load_template(name, globals)
  File "D:\CODE\python\lib\site-packages\jinja2\environment.py", line 958, in _load_template
    template = self.loader.load(self, name, self.make_globals(globals))
  File "D:\CODE\python\lib\site-packages\jinja2\loaders.py", line 137, in load
    code = environment.compile(source, name, filename)
  File "D:\CODE\python\lib\site-packages\jinja2\environment.py", line 757, in compile
    self.handle_exception(source=source_hint)
  File "D:\CODE\python\lib\site-packages\jinja2\environment.py", line 925, in handle_exception
    raise rewrite_traceback_stack(source=source)
  File "D:\WS\WORK\crmdancer-master\templates\crm_index.html", line 497, in template
    {% endblock %}
jinja2.exceptions.TemplateSyntaxError: Encountered unknown tag 'endblock'.
2021-08-22 15:15:44,807 ERROR: Exception on /area/crm/ [GET] [in D:\CODE\python\lib\site-packages\flask\app.py:1454]
Traceback (most recent call last):
  File "D:\CODE\python\lib\site-packages\flask\app.py", line 2070, in wsgi_app
    response = self.full_dispatch_request()
  File "D:\CODE\python\lib\site-packages\flask\app.py", line 1515, in full_dispatch_request
    rv = self.handle_user_exception(e)
  File "D:\CODE\python\lib\site-packages\flask\app.py", line 1513, in full_dispatch_request
    rv = self.dispatch_request()
  File "D:\CODE\python\lib\site-packages\flask\app.py", line 1499, in dispatch_request
    return self.ensure_sync(self.view_functions[rule.endpoint])(**req.view_args)
  File "D:\WS\WORK\crmdancer-master\main.py", line 240, in area_crm
    return render_template("crm_index.html")
  File "D:\CODE\python\lib\site-packages\flask\templating.py", line 148, in render_template
    ctx.app.jinja_env.get_or_select_template(template_name_or_list),
  File "D:\CODE\python\lib\site-packages\jinja2\environment.py", line 1068, in get_or_select_template
    return self.get_template(template_name_or_list, parent, globals)
  File "D:\CODE\python\lib\site-packages\jinja2\environment.py", line 997, in get_template
    return self._load_template(name, globals)
  File "D:\CODE\python\lib\site-packages\jinja2\environment.py", line 958, in _load_template
    template = self.loader.load(self, name, self.make_globals(globals))
  File "D:\CODE\python\lib\site-packages\jinja2\loaders.py", line 137, in load
    code = environment.compile(source, name, filename)
  File "D:\CODE\python\lib\site-packages\jinja2\environment.py", line 757, in compile
    self.handle_exception(source=source_hint)
  File "D:\CODE\python\lib\site-packages\jinja2\environment.py", line 925, in handle_exception
    raise rewrite_traceback_stack(source=source)
  File "D:\WS\WORK\crmdancer-master\templates\crm_index.html", line 497, in template
    {% endblock %}
jinja2.exceptions.TemplateSyntaxError: Encountered unknown tag 'endblock'.
